13:4: not a valid test operator: (
13:4: not a valid test operator: 470.129.06
Traceback (most recent call last):
  File "/usr/lib/python3.8/urllib/request.py", line 1354, in do_open
    h.request(req.get_method(), req.selector, req.data, headers,
  File "/usr/lib/python3.8/http/client.py", line 1256, in request
    self._send_request(method, url, body, headers, encode_chunked)
  File "/usr/lib/python3.8/http/client.py", line 1302, in _send_request
    self.endheaders(body, encode_chunked=encode_chunked)
  File "/usr/lib/python3.8/http/client.py", line 1251, in endheaders
    self._send_output(message_body, encode_chunked=encode_chunked)
  File "/usr/lib/python3.8/http/client.py", line 1011, in _send_output
    self.send(msg)
  File "/usr/lib/python3.8/http/client.py", line 951, in send
    self.connect()
  File "/usr/lib/python3.8/http/client.py", line 1418, in connect
    super().connect()
  File "/usr/lib/python3.8/http/client.py", line 922, in connect
    self.sock = self._create_connection(
  File "/usr/lib/python3.8/socket.py", line 808, in create_connection
    raise err
  File "/usr/lib/python3.8/socket.py", line 796, in create_connection
    sock.connect(sa)
OSError: [Errno 113] No route to host

During handling of the above exception, another exception occurred:

Traceback (most recent call last):
  File "prune.py", line 564, in <module>
    main()
  File "prune.py", line 554, in main
    perf_exper(logger, args, device, run_dir)
  File "prune.py", line 511, in perf_exper
    all_acc, conn = perf_lth(logger, device, args, controller)
  File "prune.py", line 360, in perf_lth
    data = Data(args.batch_size, C.DATA_DIR, args.dataset)
  File "/home/gharatappeh/nips/src/data_loader.py", line 56, in __init__
    training_data = datasets.CIFAR100(
  File "/home/gharatappeh/.local/lib/python3.8/site-packages/torchvision/datasets/cifar.py", line 65, in __init__
    self.download()
  File "/home/gharatappeh/.local/lib/python3.8/site-packages/torchvision/datasets/cifar.py", line 139, in download
    download_and_extract_archive(self.url, self.root, filename=self.filename, md5=self.tgz_md5)
  File "/home/gharatappeh/.local/lib/python3.8/site-packages/torchvision/datasets/utils.py", line 447, in download_and_extract_archive
    download_url(url, download_root, filename, md5)
  File "/home/gharatappeh/.local/lib/python3.8/site-packages/torchvision/datasets/utils.py", line 147, in download_url
    url = _get_redirect_url(url, max_hops=max_redirect_hops)
  File "/home/gharatappeh/.local/lib/python3.8/site-packages/torchvision/datasets/utils.py", line 95, in _get_redirect_url
    with urllib.request.urlopen(urllib.request.Request(url, headers=headers)) as response:
  File "/usr/lib/python3.8/urllib/request.py", line 222, in urlopen
    return opener.open(url, data, timeout)
  File "/usr/lib/python3.8/urllib/request.py", line 525, in open
    response = self._open(req, data)
  File "/usr/lib/python3.8/urllib/request.py", line 542, in _open
    result = self._call_chain(self.handle_open, protocol, protocol +
  File "/usr/lib/python3.8/urllib/request.py", line 502, in _call_chain
    result = func(*args)
  File "/usr/lib/python3.8/urllib/request.py", line 1397, in https_open
    return self.do_open(http.client.HTTPSConnection, req,
  File "/usr/lib/python3.8/urllib/request.py", line 1357, in do_open
    raise URLError(err)
urllib.error.URLError: <urlopen error [Errno 113] No route to host>
